<?xml version="1.0"?>

<!-- 
    ############################################
    ######              MEMO              ######
    ############################################
    x = front
    y = left
    z = up
    
    Origin is placed at geometry center of the body 

    https://mymodelrobot.appspot.com/6312011906416640
-->

<robot name="mini_pupper">

    <material name="white">
        <color rgba="0.9 0.9 0.9 1.0"/>
    </material>
    <material name="black">
        <color rgba="0.2 0.2 0.2 1.0"/>
    </material>
    <material name="dark_grey">
        <color rgba="0.3 0.3 0.3 1.0"/>
    </material>    
    <material name="grey">
        <color rgba="0.6 0.6 0.6 1.0"/>
    </material>

    <!-- 
    ############################################
    ######              BODY              ######
    ############################################
    -->

    <!--
    ********************************************
    ******              PARTS             ******
    ********************************************
    -->
    <link name="base_link">
        <!--body-->
        <visual>
            <geometry>
                <mesh filename="meshes/base_link.STL" scale="1.0 1.0 1.0"/>
            </geometry>
            <origin rpy="0 0 0" xyz="0 0 -0.017"/>
            <material name="white"/>          
        </visual>
        <collision>
            <geometry>
                <box size="0.180 0.060 0.045"/>
            </geometry>
            <origin rpy="0 0 0" xyz="0.008 0 0.005"/>
        </collision>

        <!--body-battery-holder-->
        <visual>
            <geometry>
                <box size="0.150 0.036 0.008"/>
            </geometry>
            <origin rpy="0 0 0" xyz="0.0 0.0 -0.020"/>
            <material name="black"/>                          
        </visual>
        <collision>
            <geometry>
                <box size="0.150 0.036 0.008"/>
            </geometry>
            <origin rpy="0 0 0" xyz="0.0 0.0 -0.020"/>
        </collision>
        <inertial>
            <origin rpy="0 0 0" xyz="0.0 0.0 0.0"/>
            <mass value="0.2"/> 
            <inertia ixx="0.02" ixy="0.0" ixz="0.0" iyy="0.03" iyz="0.0" izz="0.03"/>
        </inertial>
    </link>
        
    <!-- 
    ############################################
    ######              LEG Front Right   ######
    ############################################
    -->
    <!--
    ********************************************
    ******              PARTS             ******
    ********************************************
    -->
    <link name="FR-pod">
        <visual>
            <geometry>
                <mesh filename="meshes/rf1.STL" scale="1.0 1.0 1.0"/>
            </geometry>
            <origin rpy="0.0 1.57079 0.0" xyz="0 0 0"/>
            <material name="black"/>
        </visual>
        <collision>
            <geometry>
                <box size="0.031 0.030 0.038"/>
            </geometry>
            <origin rpy="0.0 0 0" xyz="0.006 0.0 -0.006"/>
        </collision>
        <inertial>
            <mass value="0.05"/>
            <inertia ixx="0.0003" ixy="0.0" ixz="0.0" iyy="0.0008" iyz="0.0" izz="0.0008"/>
        </inertial>        
    </link>
    
    <link name="FR-femur">
        <visual>
            <geometry>
                <mesh filename="meshes/rf2.STL" scale="1.0 1.0 1.0"/>
            </geometry>
            <origin rpy="1.57079 0.0 -1.57079" xyz="0 0 0"/>
            <material name="dark_grey"/>          
        </visual>
        <collision>
            <geometry>
                <box size="0.054 0.007 0.002"/>
            </geometry>
            <origin rpy="0.0 0.0 0.0" xyz="0.025 0.0 0.0"/>
        </collision>
        <inertial>
          <mass value="0.02"/>
          <inertia ixx="0.0001" ixy="0.0" ixz="0.0" iyy="0.0001" iyz="0.0" izz="0.0001"/>
        </inertial>      
    </link>
    
    <link name="FR-tibia">
        <visual>
            <geometry>
                <mesh filename="meshes/rf3.STL" scale="1.0 1.0 1.0"/>
            </geometry>
            <origin rpy="1.57079 0.0 -1.57079" xyz="0.000 0 0"/>
            <material name="grey"/>  
        </visual>
        <collision>
            <geometry>
                <box size="0.060 0.006 0.002"/>
            </geometry>
            <origin rpy="0 0 0" xyz="0.030 0 0"/>
        </collision>
        <inertial>
          <mass value="0.01"/>
          <inertia ixx="0.0001" ixy="0.0" ixz="0.0" iyy="0.0001" iyz="0.0" izz="0.0001"/>
        </inertial>      
    </link>

    <link name="FR-foot"/>

    <!--
    ********************************************
    ******             JOINTS             ******
    ********************************************
    -->
    <joint name="FR-ABD" type="revolute">
        <parent link="base_link"/>
        <child link="FR-pod"/>
        <origin rpy="0 -1.57079 0" xyz="0.059 -0.0235 0"/>
        <axis xyz="0 0 1"/>
        <limit lower="-0.4" upper="0.4" effort="100" velocity="1000"/>      
    </joint>
    
    <joint name="FR-HIPS" type="revolute">
        <parent link="FR-pod"/>
        <child link="FR-femur"/>
        <origin rpy="-1.57079 1.57079 0" xyz="0.0 -0.019 0.0"/>
        <axis xyz="0 0 1"/>
        <limit lower="0.0" upper="3.4" effort="100" velocity="1000"/>
    </joint>
    
    <joint name="FR-KNEE" type="revolute">
        <parent link="FR-femur"/>
        <child link="FR-tibia"/>
        <origin rpy="0 0 0" xyz="0.050 0 -0.005"/>
        <axis xyz="0 0 1"/>
        <limit lower="-2.8" upper="0.0" effort="100" velocity="1000"/>
    </joint>
    
    <joint name="FR-FOOT" type="fixed">
        <parent link="FR-tibia"/>
        <child link="FR-foot"/>
        <origin rpy="0 0 0" xyz="0.060 0 0"/>
        <axis xyz="0 0 1"/>
    </joint>

    <!-- 
    ############################################
    ######              LEG Front Left   ######
    ############################################
    -->
    <!--
    ********************************************
    ******              PARTS             ******
    ********************************************
    -->
    <link name="FL-pod">
        <visual>
            <geometry>
                <mesh filename="meshes/lf1.STL" scale="1.0 1.0 1.0"/>
            </geometry>
            <origin rpy="0.0 1.57079 0.0" xyz="0 0 0"/>
            <material name="black"/>
        </visual>
        <collision>
            <geometry>
                <box size="0.031 0.030 0.038"/>
            </geometry>
            <origin rpy="0.0 0 0" xyz="0.006 0.0 -0.006"/>
        </collision>
        <inertial>
            <mass value="0.05"/>
            <inertia ixx="0.0003" ixy="0.0" ixz="0.0" iyy="0.0008" iyz="0.0" izz="0.0008"/>
        </inertial>        
    </link>
    
    <link name="FL-femur">
        <visual>
            <geometry>
                <mesh filename="meshes/lf2.STL" scale="1.0 1.0 1.0"/>
            </geometry>
            <origin rpy="1.57079 0.0 -1.57079" xyz="0 0 0"/>
            <material name="dark_grey"/>      
        </visual>
        <collision>
            <geometry>
                <box size="0.054 0.007 0.002"/>
            </geometry>
            <origin rpy="0.0 0.0 0.0" xyz="0.025 0.0 0.0"/>
        </collision>
        <inertial>
          <mass value="0.02"/>
          <inertia ixx="0.0001" ixy="0.0" ixz="0.0" iyy="0.0001" iyz="0.0" izz="0.0001"/>
        </inertial>      
    </link>
    
    <link name="FL-tibia">
        <visual>
            <geometry>
                <mesh filename="meshes/lf3.STL" scale="1.0 1.0 1.0"/>
            </geometry>
            <origin rpy="1.57079 0.0 -1.57079" xyz="0.000 0 0"/>
            <material name="grey"/>           
        </visual>
        <collision>
            <geometry>
                <box size="0.060 0.006 0.002"/>
            </geometry>
            <origin rpy="0 0 0" xyz="0.030 0 0"/>
        </collision>
        <inertial>
          <mass value="0.01"/>
          <inertia ixx="0.0001" ixy="0.0" ixz="0.0" iyy="0.0001" iyz="0.0" izz="0.0001"/>
        </inertial>      
    </link>

    <link name="FL-foot"/>
    
    <!--
    ********************************************
    ******             JOINTS             ******
    ********************************************
    -->
    <joint name="FL-ABD" type="revolute">
        <parent link="base_link"/>
        <child link="FL-pod"/>
        <origin rpy="0 -1.57079 0" xyz="0.059 0.0235 0"/>
        <axis xyz="0 0 1"/>
        <limit lower="-0.4" upper="0.4" effort="100" velocity="1000"/>      
    </joint>
    
    <joint name="FL-HIPS" type="revolute">
        <parent link="FL-pod"/>
        <child link="FL-femur"/>
        <origin rpy="-1.57079 1.57079 0" xyz="0.0 0.019 0.0"/>       
        <axis xyz="0 0 1"/>
        <limit lower="0.0" upper="3.4" effort="100" velocity="1000"/>
    </joint>
    
    <joint name="FL-KNEE" type="revolute">
        <parent link="FL-femur"/>
        <child link="FL-tibia"/>
        <origin rpy="0 0 0" xyz="0.050 0 0.005"/>
        <axis xyz="0 0 1"/>
        <limit lower="-2.8" upper="0.0" effort="100" velocity="1000"/>
    </joint>
    
    <joint name="FL-FOOT" type="fixed">
        <parent link="FL-tibia"/>
        <child link="FL-foot"/>
        <origin rpy="0 0 0" xyz="0.060 0 0"/>
        <axis xyz="0 0 1"/>
    </joint>

    <!-- 
    ############################################
    ######              LEG Rear Right   ######
    ############################################
    -->
    <!--
    ********************************************
    ******              PARTS             ******
    ********************************************
    -->
    <link name="RR-pod">
        <visual>
            <geometry>
                <mesh filename="meshes/rb1.STL" scale="1.0 1.0 1.0"/>
            </geometry>
            <origin rpy="0.0 1.57079 0.0" xyz="0 0 0"/>
            <material name="black"/>
        </visual>
        <collision>
            <geometry>
                <box size="0.031 0.030 0.038"/>
            </geometry>
            <origin rpy="0.0 0 0" xyz="0.006 0.0 -0.006"/>
        </collision>
        <inertial>
            <mass value="0.05"/>
            <inertia ixx="0.0003" ixy="0.0" ixz="0.0" iyy="0.0008" iyz="0.0" izz="0.0008"/>
        </inertial>           
    </link>
    

    <link name="RR-femur">
        <visual>
            <geometry>
                <mesh filename="meshes/rb2.STL" scale="1.0 1.0 1.0"/>
            </geometry>
            <origin rpy="1.57079 0.0 -1.57079" xyz="0 0 0"/>
            <material name="dark_grey"/>
        </visual>
        <collision>
            <geometry>
                <box size="0.054 0.007 0.002"/>
            </geometry>
            <origin rpy="0.0 0.0 0.0" xyz="0.025 0.0 0.0"/>
        </collision>
        <inertial>
          <mass value="0.02"/>
          <inertia ixx="0.0001" ixy="0.0" ixz="0.0" iyy="0.0001" iyz="0.0" izz="0.0001"/>
        </inertial>      
    </link>
    
    <link name="RR-tibia">
        <visual>
            <geometry>
                <mesh filename="meshes/rb3.STL" scale="1.0 1.0 1.0"/>
            </geometry>
            <origin rpy="1.57079 0.0 -1.57079" xyz="0.000 0 0"/>
            <material name="grey"/>     
        </visual>
        <collision>
            <geometry>
                <box size="0.060 0.006 0.002"/>
            </geometry>
            <origin rpy="0 0 0" xyz="0.030 0 0"/>
        </collision>
        <inertial>
          <mass value="0.01"/>
          <inertia ixx="0.0001" ixy="0.0" ixz="0.0" iyy="0.0001" iyz="0.0" izz="0.0001"/>
        </inertial>      
    </link>

    <link name="RR-foot"/>

    <!--
    ********************************************
    ******             JOINTS             ******
    ********************************************
    -->
    <joint name="RR-ABD" type="revolute">
        <parent link="base_link"/>
        <child link="RR-pod"/>
        <origin rpy="0 -1.57079 0" xyz="-0.059 -0.0235 0"/>
        <axis xyz="0 0 1"/>
        <limit lower="-0.4" upper="0.4" effort="100" velocity="1000"/> 
    </joint>
    
    <joint name="RR-HIPS" type="revolute">
        <parent link="RR-pod"/>
        <child link="RR-femur"/>
        <origin rpy="-1.57079 1.57079 0" xyz="0.0 -0.019 0.0"/>
        <axis xyz="0 0 1"/>
        <limit lower="0.0" upper="3.4" effort="100" velocity="1000"/>
    </joint>
    
    <joint name="RR-KNEE" type="revolute">
        <parent link="RR-femur"/>
        <child link="RR-tibia"/>
        <origin rpy="0 0 0" xyz="0.050 0 -0.005"/>
        <axis xyz="0 0 1"/>
        <limit lower="-2.8" upper="0.0" effort="100" velocity="1000"/>
    </joint>
    
    <joint name="RR-FOOT" type="fixed">
        <parent link="RR-tibia"/>
        <child link="RR-foot"/>
        <origin rpy="0 0 0" xyz="0.060 0 0"/>
        <axis xyz="0 0 1"/>
    </joint>

    <!-- 
    ############################################
    ######              Leg Rear Left    ######
    ############################################
    -->
    <!--
    ********************************************
    ******              PARTS             ******
    ********************************************
    -->
    <link name="RL-pod">
        <visual>
            <geometry>
                <mesh filename="meshes/lb1.STL" scale="1.0 1.0 1.0"/>
            </geometry>
            <origin rpy="0.0 1.57079 0.0" xyz="0 0 0"/>
            <material name="black"/>
        </visual>
        <collision>
            <geometry>
                <box size="0.031 0.030 0.038"/>
            </geometry>
            <origin rpy="0.0 0 0" xyz="0.006 0.0 -0.006"/>
        </collision>
        <inertial>
            <mass value="0.05"/>
            <inertia ixx="0.0003" ixy="0.0" ixz="0.0" iyy="0.0008" iyz="0.0" izz="0.0008"/>
        </inertial>        
    </link>
    
    <link name="RL-femur">
        <visual>
            <geometry>
                <mesh filename="meshes/lb2.STL" scale="1.0 1.0 1.0"/>
            </geometry>
            <origin rpy="1.57079 0.0 -1.57079" xyz="0 0 0"/>
           <material name="dark_grey"/>     
        </visual>
        <collision>
            <geometry>
                <box size="0.054 0.007 0.002"/>
            </geometry>
            <origin rpy="0.0 0.0 0.0" xyz="0.025 0.0 0.0"/>
        </collision>
        <inertial>
          <mass value="0.02"/>
          <inertia ixx="0.0001" ixy="0.0" ixz="0.0" iyy="0.0001" iyz="0.0" izz="0.0001"/>
        </inertial>      
    </link>
    
    <link name="RL-tibia">
        <visual>
            <geometry>
                <mesh filename="meshes/lb3.STL" scale="1.0 1.0 1.0"/>
            </geometry>
            <origin rpy="1.57079 0.0 -1.57079" xyz="0.000 0 0"/>
            <material name="grey"/>         
        </visual>
        <collision>
            <geometry>
                <box size="0.060 0.006 0.002"/>
            </geometry>
            <origin rpy="0 0 0" xyz="0.030 0 0"/>
        </collision>
        <inertial>
          <mass value="0.01"/>
          <inertia ixx="0.0001" ixy="0.0" ixz="0.0" iyy="0.0001" iyz="0.0" izz="0.0001"/>
        </inertial>      
    </link>

    <link name="RL-foot"/>
    
    <!--
    ********************************************
    ******             JOINTS             ******
    ********************************************
    -->
    <joint name="RL-ABD" type="revolute">
        <parent link="base_link"/>
        <child link="RL-pod"/>
        <origin rpy="0 -1.57079 0" xyz="-0.059 0.0235 0"/>
        <axis xyz="0 0 1"/>
        <limit lower="-0.4" upper="0.4" effort="100" velocity="1000"/>      
    </joint>
    
    <joint name="RL-HIPS" type="revolute">
        <parent link="RL-pod"/>
        <child link="RL-femur"/>
        <origin rpy="-1.57079 1.57079 0" xyz="0.0 0.019 0.0"/>       
        <axis xyz="0 0 1"/>
        <limit lower="0.0" upper="3.4" effort="100" velocity="1000"/>
    </joint>
    
    <joint name="RL-KNEE" type="revolute">
        <parent link="RL-femur"/>
        <child link="RL-tibia"/>
        <origin rpy="0 0 0" xyz="0.050 0 0.005"/>
        <axis xyz="0 0 1"/>
        <limit lower="-2.8" upper="0.0" effort="100" velocity="1000"/>
    </joint>
    
    <joint name="RL-FOOT" type="fixed">
        <parent link="RL-tibia"/>
        <child link="RL-foot"/>
        <origin rpy="0 0 0" xyz="0.060 0 0"/>
        <axis xyz="0 0 1"/>
    </joint>

</robot>    